Workbook

Sheet CALCULO
A1: MUROS DE CONTENCION
A3: DATOS: | H3: =B9 -> 0.2
A4: H= | B4: 4 | C4: m | I4: =B4-J15 -> 3.6
A5: sADM= | B5: 10.5 | C5: Tn/m2
AS6: ZONA | AT6: Z(g)
A7: 1. PREDIMENSIONAMIENTO | AS7: 1 | AT7: 0.4
Q8: H= | R8: =B4 -> 4 | S8: m | AS8: 2 | AT8: 0.3
A9: PUNTA= | B9: 0.2 | C9: m | L9: H | M9: =ATAN(I4/F11) -> 1.5152978 | AS9: 3 | AT9: 0.15
M10: =ATAN(48) -> 1.549966 | N10: =I4/M10 -> 2.3226316
A11: BASE DE LA PANTALLA | F11: =G17-H3 -> 0.2 | R11: MONONOBE-OKABE | AS11: 0.3Kh | AT11: =0.3*T13 -> 0.045
A12: K= | B12: 10 | R12: ZONA: | S12: 2 | T12: =VLOOKUP(S12,AS6:AT9,2,FALSE) -> 0.3 | AS12: 0.35Kh | AT12: =0.35*T13 -> 0.0525
A13: PERALTE DE LA ZAPATA | S13: Kh= | T13: =T12/2 -> 0.15 | AS13: 0.4Kh | AT13: =0.4*T13 -> 0.06
A14: K= | B14: 10 | R14: Kv esta en el rango de 0.3-0.6 Kh | U14: 0.3Kh | AS14: 0.45Kh | AT14: =0.45*T13 -> 0.0675
A15: ANCHO DE LA ZAPATA | J15: =B4/B14 -> 0.4 | S15: Kv= | T15: =VLOOKUP(U14,AS11:AT15,2,FALSE) -> 0.045 | AS15: 0.5Kh | AT15: =0.5*T13 -> 0.075
A16: K= | B16: 0.7
F17: =G18/3 -> 0.93333333 | G17: =B4/B12 -> 0.4 | S17: ° | T17: RAD
G18: =B16*B4 -> 2.8 | R18: Θ= | S18: =DEGREES(T18) -> 8.9264079 | T18: =ATAN(T13/(1-T15)) -> 0.15579521 | AS18: =COS(T19-T18-T20) -> 0.93058639 | AT18: =SIN(T21+T19) -> 0.50603376
R19: Ø= | S19: =B24 -> 30.4 | T19: =RADIANS(S19) -> 0.53058009 | U19: SUELO | AS19: =COS(T18)*COS(T20)*COS(T20)*COS(T20+T21+T18) -> 0.9759236 | AT19: =SIN(T19-T18-T22) -> 0.36607235
R20: BETA | S20: 0 | T20: =RADIANS(S20) -> 0 | U20: ANGULO VASTAGO | AT20: =COS(T21+T20+T18) -> 0.98788845
A21: 2. PRESION DEL SUELO | H21: S/C= | I21: =B27 -> 0.4 | R21: d= | S21: 0 | T21: =RADIANS(S21) -> 0 | U21: ANGULO DE FRICCION | AT21: =COS(T22-T20) -> 1
A22: gc= | B22: 2.4 | C22: Tn/m3 | R22: I= | S22: =B26 -> 0 | T22: 0 | U22: ANGULO DEL TALUD | AT22: =POWER(AT18*AT19/(AT20*AT21),0.5) -> 0.43303127
A23: gs= | B23: 2.03 | C23: Tn/m3 | H23: =H3 -> 0.2
A24: Ø= | B24: 30.4 | C24: ° | D24: =RADIANS(B24) -> 0.53058009 | E24: Rad | I24: =I4 -> 3.6 | R24: y= | S24: =POWER(1+AT22,2) -> 2.0535786
A25: z= | B25: 0 | S25: KAE= | T25: =AS18*AS18/(S24*AS19) -> 0.43210196
A26: d= | B26: 0 | C26: ° | D26: =RADIANS(B26) -> 0 | E26: Rad
A27: S/C= | B27: 0.4 | C27: Tn/m2 | R27: gs= | S27: =B23 -> 2.03 | AS27: cosΦ | AT27: =COS(D24) -> 0.86251367
A28: hs= | B28: =B27/B23 -> 0.19704433 | C28: m | R28: H= | S28: =L48 -> 4 | AS28: cosd | AT28: =COS(D26) -> 1
A29: Ka= | B29: =AT33 -> 0.32799148 | R29: Kv= | S29: =T15 -> 0.045 | AS29: cosΦ2 | AT29: =POWER(COS(D24),2) -> 0.74392983
A30: Kp= | B30: =AU33 -> 3.0488597 | AS30: cosd2 | AT30: =POWER(COS(D26),2) -> 1
A31: Ko= | B31: =1-SIN(D24) -> 0.49396624 | F31: =F11 -> 0.2 | S31: EAE= | T31: =0.5*S27*(1-S29)*T25*S28*S28 -> 6.7015558 | U31: Tn | AS31: 1 | AT31: =AT28-POWER(AT30-AT29,0.5) -> 0.49396624 | AU31: =AT28+POWER(AT30-AT29,0.5) -> 1.5060338
B32: SUELO | C32: S/C | D32: TOTAL | AS32: 2 | AT32: =AT28+POWER(AT30-AT29,0.5) -> 1.5060338 | AU32: =AT28-POWER(AT30-AT29,0.5) -> 0.49396624
A33: H= | B33: =VLOOKUP(B39,AS37:AT38,2,FALSE) -> 4 | C33: =B28 -> 0.19704433 | R33: Kah= | S33: =B29 -> 0.32799148 | AS33: KA | AT33: =AT28*AT31/AT32 -> 0.32799148 | AU33: =AT28*AU31/AU32 -> 3.0488597
A34: sMAX= | B34: =B23*B29*(B33) -> 2.6632908 | C34: =B23*B29*(C33) -> 0.13119659 | D34: =B34+C34 -> 2.7944874
A35: P= | B35: =B34*B33/2 -> 5.3265816 | C35: =C34*B33 -> 0.52478636 | D35: =B35+C35 -> 5.8513679 | J35: =J15 -> 0.4 | S35: Ea= | T35: =0.5*S27*S33*S28*S28 -> 5.3265816 | U35: Tn
A36: Pv= | B36: =B35*SIN(D26) -> 0 | C36: =C35*SIN(D26) -> 0 | D36: =B36+C36 -> 0 | AS36: =B4+J70 -> 4 | AT36: =B4 -> 4
A37: Ph= | B37: =B35*COS(D26) -> 5.3265816 | C37: =C35*COS(D26) -> 0.52478636 | D37: =B37+C37 -> 5.8513679 | F37: =F17 -> 0.93333333 | G37: =G17 -> 0.4 | I37: =G38-F37-G37 -> 1.4666667 | S37: DEAE= | T37: =T31-T35 -> 1.3749742 | U37: Tn | V37: Fuerza Horizontal | AS37: SI | AT37: =AS36 -> 4
G38: =G18 -> 2.8 | S38: POSICION | AS38: NO | AT38: =AT36 -> 4
A39: CONSIDERARMOS? | B39: NO | S39: 0.6H= | T39: =S28*0.6 -> 2.4 | U39: m
S40: MAE= | T40: =T37*T39 -> 3.2999382 | U40: Tn-m | V40: Momento
A41: 3. VERIFICACIONES | H41: MODIFICAR DIMENSIONES
...

Sheet ESQUEMAS
A2: SECCION DEL MURO DE CONTENCIÓN | G2: CARGAS ACTUANTES | N2: DIAGRAMA DE MOMENTOS FLECTORES | U2: DIAGRAMA DE FUERZAS CORTANTES | AB2: DISTRIBUCION DEL REFUERZO | AQ2: ACERO DE REFUERZO
D3: UNIDAD: m | K3: UNIDAD: Tn/m | R3: UNIDAD: Tn-m | Y3: UNIDAD: Tn | AK3: UNIDAD: m | AU3: UNIDAD: cm2
C4: =CALCULO!J43 -> 0.2 | J4: =CALCULO!AW95 -> 0.52478636
D5: =CALCULO!L48 -> 4
AH6: =CALCULO!A161 -> 1 | AI6: Ø | AJ6: =CALCULO!C157 -> 5/8" | AK6: @ | AL6: =CALCULO!E161 -> 25
AB8: =CALCULO!A170 -> 1 | AC8: Ø | AD8: =CALCULO!C170 -> 5/8" | AE8: @ | AF8: =CALCULO!E170 -> 25 | AR8: PANTALLA
K9: =CALCULO!U94 -> 1.3749742
AB11: =CALCULO!A217 -> 1 | AC11: Ø | AD11: =CALCULO!C217 -> 3/4" | AE11: @ | AF11: =CALCULO!E217 -> 20
A12: =CALCULO!H52 -> 0.2
AH13: =1 -> 1 | AI13: Ø | AJ13: =CALCULO!C151 -> 1" | AK13: @ | AL13: =CALCULO!E151 -> 20
H14: PANTALLA | K14: =CALCULO!AW96 -> 2.7944874 | O14: PANTALLA | R14: =CALCULO!B119 -> 20.726344 | V14: PANTALLA | Y14: =CALCULO!B120 -> 11.235316 | AQ14: PUNTA | AT14: =CALCULO!D143 -> 16.075516 | AU14: =CALCULO!P143 -> 12
E16: =CALCULO!M55 -> 0.7 | K16: =CALCULO!AW103 -> 8.52
G17: PUNTA | J17: TALON | N17: PUNTA | O17: =CALCULO!H119 -> 81.248298 | Q17: TALON | R17: =CALCULO!N119 -> 4.1260482 | U17: PUNTA | V17: =CALCULO!H120 -> 39.567902 | X17: TALON | Y17: =CALCULO!N120 -> 2.9801927 | AM17: RECORTE DE ACERO PANTALLA:
A18: =CALCULO!H58 -> 3.5 | B18: =CALCULO!I57 -> 0.4 | D18: =CALCULO!K58 -> 1 | AH18: =CALCULO!A210 -> 1 | AI18: Ø | AJ18: =CALCULO!C210 -> 1" | AK18: @ | AL18: =CALCULO!E151 -> 20 | AM18: h= | AN18: =CALCULO!B187 -> 0 | AO18: m | AR18: =CALCULO!J143 -> 38.771232 | AU18: TALON
B19: =CALCULO!I59 -> 4.9
AS20: DIENTE
A21: =CALCULO!B67 -> EN EL CENTRO | C21: =CALCULO!I67 -> 0.4 | AB21: =CALCULO!G190 -> 1 | AC21: Ø | AD21: =CALCULO!I190 -> 3/4" | AE21: @ | AF21: =CALCULO!K190 -> 20 | AH21: =CALCULO!M151 -> 1 | AI21: Ø | AJ21: =CALCULO!O151 -> 5/8" | AK21: @ | AL21: =CALCULO!Q151 -> 17 | AM21: USAR UN PEDESTAL: | AT21: =CALCULO!V143 -> 6
AB22: =CALCULO!G161 -> 1 | AC22: Ø | AD22: =CALCULO!I161 -> 5/8" | AE22: @ | AF22: =CALCULO!K161 -> 25 | AH22: =CALCULO!M161 -> 1 | AI22: Ø | AJ22: =CALCULO!O161 -> 1/2" | AK22: @ | AL22: =CALCULO!Q161 -> 21 | AM22: L= | AN22: =CALCULO!N186 -> 0 | AO22: m
D23: =CALCULO!J70 -> 0 | G23: =CALCULO!AW100 -> 1.7848612 | H23: =CALCULO!AW99 -> 5.3120922 | K23: =CALCULO!AW105 -> 2.6916651 | L23: =CALCULO!AW104 -> 6.2282 | AM23: h'= | AN23: =CALCULO!P188 -> 0 | AO23: cm
P24: DIENTE | W24: DIENTE
I25: DIENTE | R25: =CALCULO!U116 -> 0 | Y25: =CALCULO!U117 -> 0
K26: =CALCULO!AW107 -> 3.2605633 | AM26: RECORTE DE ACERO TALON:
AB27: =CALCULO!G170 -> 1 | AC27: Ø | AD27: =CALCULO!I170 -> 3/4" | AE27: @ | AF27: =CALCULO!K170 -> 25 | AH27: =CALCULO!M170 -> 1 | AI27: Ø | AJ27: =CALCULO!O170 -> 1/2" | AK27: @ | AL27: =CALCULO!Q170 -> 21 | AM27: L1= | AN27: =CALCULO!N193 -> 0 | AO27: m
AB28: =CALCULO!G151 -> 1 | AC28: Ø | AD28: =CALCULO!I151 -> 3/4" | AE28: @ | AF28: =CALCULO!K151 -> 7 | AH28: =CALCULO!G190 -> 1 | AI28: Ø | AJ28: =CALCULO!I190 -> 3/4" | AK28: @ | AL28: =CALCULO!K190 -> 20
K29: =CALCULO!AW108 -> 3.2605633
AB30: =CALCULO!S170 -> 1 | AC30: Ø | AD30: =CALCULO!U170 -> 5/8" | AE30: @ | AF30: =CALCULO!W170 -> 25 | AH30: =CALCULO!S161 -> 1 | AI30: Ø | AJ30: =CALCULO!U161 -> 5/8" | AK30: @ | AL30: =CALCULO!W161 -> 25
AH31: =CALCULO!S151 -> 1 | AI31: Ø | AJ31: =CALCULO!U151 -> 3/4" | AK31: @ | AL31: =CALCULO!W151 -> 20

Sheet Hoja1
H1: S/C= | I1: =B34 -> 0 | AT1: =COS(T2-#REF!) -> #REF!
AT2: =POWER(#REF!*#REF!/(#REF!*AT1),0.5) -> #REF!
H3: =#REF! -> #REF!
I4: =#REF! -> #REF!
F11: =#REF! -> #REF!
J15: =#REF! -> #REF!
AS16: =#REF!+J50 -> #REF! | AT16: =#REF! -> #REF!
F17: =#REF! -> #REF! | G17: =#REF! -> #REF! | I17: =G18-F17-G17 -> #REF! | AS17: SI | AT17: 3
G18: =#REF! -> #REF! | AS18: NO | AT18: 3
B19: NO
A28: 2. PRESION DEL SUELO | G28: RANKINE | K28: COULUMB | AH28: Ka | AI28: Kp
A29: gc= | B29: 2.4 | C29: Tn/m3 | H29: Ka | I29: Kp | K29: seno (a+Ø) | L29: =SIN(D39+D31) -> 0.91495967 | M29: Ka | N29: Kp
A30: gs= | B30: 2.1 | C30: Tn/m3 | G30: cosΦ | H30: =COS(D31) -> 0.91495967 | K30: seno (a-Ø) | L30: =SIN(D39-D31) -> 0.91495967 | M30: =L34*L35/(L32*L37) -> 0.018150064 | N30: =L34*L36/(L33*L37) -> 0.30754755
A31: Ø= | B31: 23.8 | C31: ° | D31: =RADIANS(B31) -> 0.41538836 | E31: Rad | G31: cosd | H31: =COS(D33) -> 0.93105582 | K31: seno (a) | L31: =SIN(D39) -> 1 | M31: =POWER(POWER(M30,0.5)+1,2) -> 1.2875944 | N31: =POWER(1-POWER(N30,0.5),2) -> 0.19840816 | AC31: 2. PRESION DEL SUELO | AK31: α RAD | AL31: =D33 -> 0.37350046
A32: z= | B32: =R13 | G32: cosΦ2 | H32: =H30*H30 -> 0.83715119 | K32: seno (a-d) | L32: =SIN(D39-D40) -> 1 | M32: =M31*L32*L31*L31 -> 1.2875944 | N32: =N31*L33*L31*L31 -> 0.19840816 | AC32: gc= | AD32: 2.4 | AE32: Tn/m3 | AK32: Ø RAD | AL32: =D31 -> 0.41538836
A33: b= | B33: 21.4 | C33: ° | D33: =RADIANS(B33) -> 0.37350046 | E33: Rad | G33: cosd2 | H33: =H31*H31 -> 0.86686493 | K33: seno (a+d) | L33: =SIN(D39+D40) -> 1 | M33: =L29*L29/M32 -> 0.65016684 | N33: =L30*L30/N32 -> 4.2193386 | AC33: gs= | AD33: 2.1 | AE33: Tn/m3 | AK33: S/C= | AL33: 0
A34: S/C= | B34: 0 | C34: Tn/m2 | G34: 1 | H34: =H31-POWER(H33-H32,0.5) -> 0.75867908 | I34: =POWER((H33-H32),0.5)+H31 -> 1.1034325 | K34: seno (Ø+d) | L34: =SIN(D31+D40) -> 0.4035453 | AC34: Ø= | AD34: 26 | AE34: ° | AF34: =RADIANS(AD34) -> 0.45378561 | AG34: Rad | AK34: Cah= | AL34: =COS(AL31)*(COS(AL31)-((COS(AL31))^2-(COS(AL32))^2)^0.5)/(COS(AL31)+((COS(AL31))^2-(COS(AL32))^2)^0.5) -> 0.64015927
A35: hs= | B35: =B34/B30 -> 0 | C35: m | G35: 2 | H35: =H31+POWER(H33-H32,0.5) -> 1.1034325 | I35: =H31-POWER(H33-H32,0.5) -> 0.75867908 | K35: seno (Ø-β) | L35: =SIN(D31-D33) -> 0.041875654 | AC35: z= | AD35: 0 | AK35: Cph= | AL35: =COS(AL31)*(COS(AL31)+((COS(AL31))^2-(COS(AL32))^2)^0.5)/(COS(AL31)-((COS(AL31))^2-(COS(AL32))^2)^0.5) -> 1.3541395
A36: Ka= | B36: =H36 -> 0.64015927 | H36: =H31*H34/H35 -> 0.64015927 | I36: =H31*I34/I35 -> 1.3541395 | K36: seno (Ø+β) | L36: =SIN(D31+D33) -> 0.70957074 | AC36: d= | AD36: 17 | AE36: ° | AF36: =RADIANS(AD36) -> 0.29670597 | AG36: Rad
A37: Kp= | B37: =I36 -> 1.3541395 | K37: seno (a+β) | L37: =SIN(D39-D33) -> 0.93105582 | AC37: S/C= | AD37: 0 | AE37: Tn/m2 | AH37: 1 | AI37: =#REF!-POWER(#REF!-#REF!,0.5) -> #REF! | AJ37: =#REF!+POWER(#REF!-#REF!,0.5) -> #REF!
AC38: hs= | AD38: =AD37/AD33 -> 0 | AE38: m | AH38: 2 | AI38: =#REF!+POWER(#REF!-#REF!,0.5) -> #REF! | AJ38: =#REF!-POWER(#REF!-#REF!,0.5) -> #REF!
A39: a= | B39: 90 | C39: ° | D39: =RADIANS(B39) -> 1.5707963 | E39: Rad | AC39: Ka= | AD39: =AI39 -> #REF! | AI39: =#REF!*AI37/AI38 -> #REF! | AJ39: =#REF!*AJ37/AJ38 -> #REF!
A40: d= | B40: 0 | C40: ° | D40: =RADIANS(B40) -> 0 | E40: Rad | AC40: Kp= | AD40: =AJ39 -> #REF!
